Workbook

Sheet Dashboard
A1: COLLECTIONS MIS TRACKER — DASHBOARD
A2: Report Date: 01-Jul-2026
A4: Total EMI Due | C4: Total EMI Collected | E4: Overall Recovery % | G4: NPA Count
A5: =SUM('Raw Data'!E4:E63) -> 1718500 | C5: =SUM('Raw Data'!F4:F63) -> 737176 | E5: =SUM('Raw Data'!F4:F63)/SUM('Raw Data'!E4:E63)*100 -> 42.896479 | G5: =COUNTIF('Raw Data'!K4:K63,"NPA") -> 4

Sheet Raw Data
A1: Report Date: | B1: 2026-07-01
A3: Customer ID | B3: Name | C3: Collection Agent | D3: Loan Amount (₹) | E3: EMI Due (₹) | F3: EMI Collected (₹) | G3: Due Date | H3: Collection Date | I3: Outstanding (₹) | J3: Days Overdue | K3: Bucket | L3: Recovery %
A4: CUST0001 | B4: Rohan | C4: Deepak Chauhan | D4: 750000 | E4: 49000 | F4: 0 | G4: 2026-05-24 | I4: =D4-F4 -> 750000 | J4: =$B$1-G4 -> 38 | K4: =IF(J4<0,"Not Due",IF(J4<=30,"Bucket 1",IF(J4<=60,"Bucket 2",IF(J4<=90,"Bucket 3","NPA")))) -> Bucket 2 | L4: =F4/E4*100 -> 0
A5: CUST0002 | B5: Kavita | C5: Manish Bhatt | D5: 425000 | E5: 35000 | F5: 0 | G5: 2026-04-04 | I5: =D5-F5 -> 425000 | J5: =$B$1-G5 -> 88 | K5: =IF(J5<0,"Not Due",IF(J5<=30,"Bucket 1",IF(J5<=60,"Bucket 2",IF(J5<=90,"Bucket 3","NPA")))) -> Bucket 3 | L5: =F5/E5*100 -> 0
A6: CUST0003 | B6: Sameer | C6: Deepak Chauhan | D6: 900000 | E6: 38500 | F6: 0 | G6: 2026-06-16 | I6: =D6-F6 -> 900000 | J6: =$B$1-G6 -> 15 | K6: =IF(J6<0,"Not Due",IF(J6<=30,"Bucket 1",IF(J6<=60,"Bucket 2",IF(J6<=90,"Bucket 3","NPA")))) -> Bucket 1 | L6: =F6/E6*100 -> 0
A7: CUST0004 | B7: Pooja | C7: Ananya Rao | D7: 675000 | E7: 42000 | F7: 42000 | G7: 2026-05-23 | H7: 2026-07-01 | I7: =D7-F7 -> 633000 | J7: =$B$1-G7 -> 39 | K7: =IF(J7<0,"Not Due",IF(J7<=30,"Bucket 1",IF(J7<=60,"Bucket 2",IF(J7<=90,"Bucket 3","NPA")))) -> Bucket 2 | L7: =F7/E7*100 -> 100
A8: CUST0005 | B8: Ajay | C8: Deepak Chauhan | D8: 450000 | E8: 49000 | F8: 0 | G8: 2026-07-11 | I8: =D8-F8 -> 450000 | J8: =$B$1-G8 -> -10 | K8: =IF(J8<0,"Not Due",IF(J8<=30,"Bucket 1",IF(J8<=60,"Bucket 2",IF(J8<=90,"Bucket 3","NPA")))) -> Not Due | L8: =F8/E8*100 -> 0
A9: CUST0006 | B9: Meenal | C9: Manish Bhatt | D9: 800000 | E9: 7000 | F9: 4314 | G9: 2026-06-04 | H9: 2026-06-27 | I9: =D9-F9 -> 795686 | J9: =$B$1-G9 -> 27 | K9: =IF(J9<0,"Not Due",IF(J9<=30,"Bucket 1",IF(J9<=60,"Bucket 2",IF(J9<=90,"Bucket 3","NPA")))) -> Bucket 1 | L9: =F9/E9*100 -> 61.628571
A10: CUST0007 | B10: Tarun | C10: Ananya Rao | D10: 325000 | E10: 10500 | F10: 10500 | G10: 2026-07-01 | H10: 2026-07-01 | I10: =D10-F10 -> 314500 | J10: =$B$1-G10 -> 0 | K10: =IF(J10<0,"Not Due",IF(J10<=30,"Bucket 1",IF(J10<=60,"Bucket 2",IF(J10<=90,"Bucket 3","NPA")))) -> Bucket 1 | L10: =F10/E10*100 -> 100
A11: CUST0008 | B11: Shalini | C11: Manish Bhatt | D11: 350000 | E11: 40000 | F11: 19632 | G11: 2026-04-14 | H11: 2026-05-07 | I11: =D11-F11 -> 330368 | J11: =$B$1-G11 -> 78 | K11: =IF(J11<0,"Not Due",IF(J11<=30,"Bucket 1",IF(J11<=60,"Bucket 2",IF(J11<=90,"Bucket 3","NPA")))) -> Bucket 3 | L11: =F11/E11*100 -> 49.08
A12: CUST0009 | B12: Vinod | C12: Ananya Rao | D12: 850000 | E12: 20000 | F12: 0 | G12: 2026-07-07 | I12: =D12-F12 -> 850000 | J12: =$B$1-G12 -> -6 | K12: =IF(J12<0,"Not Due",IF(J12<=30,"Bucket 1",IF(J12<=60,"Bucket 2",IF(J12<=90,"Bucket 3","NPA")))) -> Not Due | L12: =F12/E12*100 -> 0
A13: CUST0010 | B13: Anjali | C13: Deepak Chauhan | D13: 200000 | E13: 12500 | F13: 8702 | G13: 2026-05-06 | H13: 2026-05-31 | I13: =D13-F13 -> 191298 | J13: =$B$1-G13 -> 56 | K13: =IF(J13<0,"Not Due",IF(J13<=30,"Bucket 1",IF(J13<=60,"Bucket 2",IF(J13<=90,"Bucket 3","NPA")))) -> Bucket 2 | L13: =F13/E13*100 -> 69.616
A14: CUST0011 | B14: Nikhil | C14: Farah Sheikh | D14: 325000 | E14: 39000 | F14: 39000 | G14: 2026-05-25 | H14: 2026-06-22 | I14: =D14-F14 -> 286000 | J14: =$B$1-G14 -> 37 | K14: =IF(J14<0,"Not Due",IF(J14<=30,"Bucket 1",IF(J14<=60,"Bucket 2",IF(J14<=90,"Bucket 3","NPA")))) -> Bucket 2 | L14: =F14/E14*100 -> 100
A15: CUST0012 | B15: Rekha | C15: Ritika Sen | D15: 700000 | E15: 25000 | F15: 25000 | G15: 2026-05-15 | H15: 2026-05-16 | I15: =D15-F15 -> 675000 | J15: =$B$1-G15 -> 47 | K15: =IF(J15<0,"Not Due",IF(J15<=30,"Bucket 1",IF(J15<=60,"Bucket 2",IF(J15<=90,"Bucket 3","NPA")))) -> Bucket 2 | L15: =F15/E15*100 -> 100
A16: CUST0013 | B16: Suraj | C16: Ananya Rao | D16: 350000 | E16: 36500 | F16: 0 | G16: 2026-07-16 | I16: =D16-F16 -> 350000 | J16: =$B$1-G16 -> -15 | K16: =IF(J16<0,"Not Due",IF(J16<=30,"Bucket 1",IF(J16<=60,"Bucket 2",IF(J16<=90,"Bucket 3","NPA")))) -> Not Due | L16: =F16/E16*100 -> 0
A17: CUST0014 | B17: Deepa | C17: Ritika Sen | D17: 925000 | E17: 19000 | F17: 10143 | G17: 2026-05-04 | H17: 2026-05-18 | I17: =D17-F17 -> 914857 | J17: =$B$1-G17 -> 58 | K17: =IF(J17<0,"Not Due",IF(J17<=30,"Bucket 1",IF(J17<=60,"Bucket 2",IF(J17<=90,"Bucket 3","NPA")))) -> Bucket 2 | L17: =F17/E17*100 -> 53.384211
A18: CUST0015 | B18: Manoj | C18: Deepak Chauhan | D18: 350000 | E18: 45000 | F18: 0 | G18: 2026-06-02 | I18: =D18-F18 -> 350000 | J18: =$B$1-G18 -> 29 | K18: =IF(J18<0,"Not Due",IF(J18<=30,"Bucket 1",IF(J18<=60,"Bucket 2",IF(J18<=90,"Bucket 3","NPA")))) -> Bucket 1 | L18: =F18/E18*100 -> 0
A19: CUST0016 | B19: Kiran | C19: Farah Sheikh | D19: 650000 | E19: 43000 | F19: 43000 | G19: 2026-06-07 | H19: 2026-06-17 | I19: =D19-F19 -> 607000 | J19: =$B$1-G19 -> 24 | K19: =IF(J19<0,"Not Due",IF(J19<=30,"Bucket 1",IF(J19<=60,"Bucket 2",IF(J19<=90,"Bucket 3","NPA")))) -> Bucket 1 | L19: =F19/E19*100 -> 100
A20: CUST0017 | B20: Ashok | C20: Ananya Rao | D20: 375000 | E20: 32000 | F20: 32000 | G20: 2026-05-30 | H20: 2026-06-01 | I20: =D20-F20 -> 343000 | J20: =$B$1-G20 -> 32 | K20: =IF(J20<0,"Not Due",IF(J20<=30,"Bucket 1",IF(J20<=60,"Bucket 2",IF(J20<=90,"Bucket 3","NPA")))) -> Bucket 2 | L20: =F20/E20*100 -> 100
A21: CUST0018 | B21: Bhavna | C21: Ritika Sen | D21: 475000 | E21: 31000 | F21: 0 | G21: 2026-06-26 | I21: =D21-F21 -> 475000 | J21: =$B$1-G21 -> 5 | K21: =IF(J21<0,"Not Due",IF(J21<=30,"Bucket 1",IF(J21<=60,"Bucket 2",IF(J21<=90,"Bucket 3","NPA")))) -> Bucket 1 | L21: =F21/E21*100 -> 0
A22: CUST0019 | B22: Girish | C22: Ritika Sen | D22: 100000 | E22: 27000 | F22: 27000 | G22: 2026-05-15 | H22: 2026-06-26 | I22: =D22-F22 -> 73000 | J22: =$B$1-G22 -> 47 | K22: =IF(J22<0,"Not Due",IF(J22<=30,"Bucket 1",IF(J22<=60,"Bucket 2",IF(J22<=90,"Bucket 3","NPA")))) -> Bucket 2 | L22: =F22/E22*100 -> 100
A23: CUST0020 | B23: Hema | C23: Deepak Chauhan | D23: 475000 | E23: 15000 | F23: 15000 | G23: 2026-05-06 | H23: 2026-06-27 | I23: =D23-F23 -> 460000 | J23: =$B$1-G23 -> 56 | K23: =IF(J23<0,"Not Due",IF(J23<=30,"Bucket 1",IF(J23<=60,"Bucket 2",IF(J23<=90,"Bucket 3","NPA")))) -> Bucket 2 | L23: =F23/E23*100 -> 100
A24: CUST0021 | B24: Imran | C24: Manish Bhatt | D24: 175000 | E24: 23000 | F24: 0 | G24: 2026-07-10 | I24: =D24-F24 -> 175000 | J24: =$B$1-G24 -> -9 | K24: =IF(J24<0,"Not Due",IF(J24<=30,"Bucket 1",IF(J24<=60,"Bucket 2",IF(J24<=90,"Bucket 3","NPA")))) -> Not Due | L24: =F24/E24*100 -> 0
A25: CUST0022 | B25: Jyoti | C25: Farah Sheikh | D25: 150000 | E25: 31500 | F25: 31500 | G25: 2026-06-15 | H25: 2026-06-17 | I25: =D25-F25 -> 118500 | J25: =$B$1-G25 -> 16 | K25: =IF(J25<0,"Not Due",IF(J25<=30,"Bucket 1",IF(J25<=60,"Bucket 2",IF(J25<=90,"Bucket 3","NPA")))) -> Bucket 1 | L25: =F25/E25*100 -> 100
A26: CUST0023 | B26: Kunal | C26: Farah Sheikh | D26: 325000 | E26: 14500 | F26: 0 | G26: 2026-04-12 | I26: =D26-F26 -> 325000 | J26: =$B$1-G26 -> 80 | K26: =IF(J26<0,"Not Due",IF(J26<=30,"Bucket 1",IF(J26<=60,"Bucket 2",IF(J26<=90,"Bucket 3","NPA")))) -> Bucket 3 | L26: =F26/E26*100 -> 0
A27: CUST0024 | B27: Lata | C27: Ananya Rao | D27: 500000 | E27: 13500 | F27: 8601 | G27: 2026-04-24 | H27: 2026-04-27 | I27: =D27-F27 -> 491399 | J27: =$B$1-G27 -> 68 | K27: =IF(J27<0,"Not Due",IF(J27<=30,"Bucket 1",IF(J27<=60,"Bucket 2",IF(J27<=90,"Bucket 3","NPA")))) -> Bucket 3 | L27: =F27/E27*100 -> 63.711111
A28: CUST0025 | B28: Mahesh | C28: Deepak Chauhan | D28: 675000 | E28: 14500 | F28: 0 | G28: 2026-03-26 | I28: =D28-F28 -> 675000 | J28: =$B$1-G28 -> 97 | K28: =IF(J28<0,"Not Due",IF(J28<=30,"Bucket 1",IF(J28<=60,"Bucket 2",IF(J28<=90,"Bucket 3","NPA")))) -> NPA | L28: =F28/E28*100 -> 0
A29: CUST0026 | B29: Neelam | C29: Manish Bhatt | D29: 875000 | E29: 42000 | F29: 0 | G29: 2026-03-23 | I29: =D29-F29 -> 875000 | J29: =$B$1-G29 -> 100 | K29: =IF(J29<0,"Not Due",IF(J29<=30,"Bucket 1",IF(J29<=60,"Bucket 2",IF(J29<=90,"Bucket 3","NPA")))) -> NPA | L29: =F29/E29*100 -> 0
A30: CUST0027 | B30: Om | C30: Farah Sheikh | D30: 300000 | E30: 39000 | F30: 39000 | G30: 2026-05-02 | H30: 2026-05-03 | I30: =D30-F30 -> 261000 | J30: =$B$1-G30 -> 60 | K30: =IF(J30<0,"Not Due",IF(J30<=30,"Bucket 1",IF(J30<=60,"Bucket 2",IF(J30<=90,"Bucket 3","NPA")))) -> Bucket 2 | L30: =F30/E30*100 -> 100
A31: CUST0028 | B31: Pallavi | C31: Manish Bhatt | D31: 300000 | E31: 6500 | F31: 3811 | G31: 2026-06-13 | H31: 2026-07-01 | I31: =D31-F31 -> 296189 | J31: =$B$1-G31 -> 18 | K31: =IF(J31<0,"Not Due",IF(J31<=30,"Bucket 1",IF(J31<=60,"Bucket 2",IF(J31<=90,"Bucket 3","NPA")))) -> Bucket 1 | L31: =F31/E31*100 -> 58.630769
A32: CUST0029 | B32: Qasim | C32: Ritika Sen | D32: 750000 | E32: 21000 | F32: 16279 | G32: 2026-04-20 | H32: 2026-05-07 | I32: =D32-F32 -> 733721 | J32: =$B$1-G32 -> 72 | K32: =IF(J32<0,"Not Due",IF(J32<=30,"Bucket 1",IF(J32<=60,"Bucket 2",IF(J32<=90,"Bucket 3","NPA")))) -> Bucket 3 | L32: =F32/E32*100 -> 77.519048
A33: CUST0030 | B33: Rani | C33: Deepak Chauhan | D33: 325000 | E33: 11000 | F33: 11000 | G33: 2026-05-27 | H33: 2026-05-28 | I33: =D33-F33 -> 314000 | J33: =$B$1-G33 -> 35 | K33: =IF(J33<0,"Not Due",IF(J33<=30,"Bucket 1",IF(J33<=60,"Bucket 2",IF(J33<=90,"Bucket 3","NPA")))) -> Bucket 2 | L33: =F33/E33*100 -> 100
A34: CUST0031 | B34: Sunil | C34: Manish Bhatt | D34: 325000 | E34: 9500 | F34: 3503 | G34: 2026-03-27 | H34: 2026-05-04 | I34: =D34-F34 -> 321497 | J34: =$B$1-G34 -> 96 | K34: =IF(J34<0,"Not Due",IF(J34<=30,"Bucket 1",IF(J34<=60,"Bucket 2",IF(J34<=90,"Bucket 3","NPA")))) -> NPA | L34: =F34/E34*100 -> 36.873684
A35: CUST0032 | B35: Tina | C35: Ritika Sen | D35: 600000 | E35: 30000 | F35: 0 | G35: 2026-05-14 | I35: =D35-F35 -> 600000 | J35: =$B$1-G35 -> 48 | K35: =IF(J35<0,"Not Due",IF(J35<=30,"Bucket 1",IF(J35<=60,"Bucket 2",IF(J35<=90,"Bucket 3","NPA")))) -> Bucket 2 | L35: =F35/E35*100 -> 0
A36: CUST0033 | B36: Umesh | C36: Ritika Sen | D36: 350000 | E36: 16500 | F36: 5296 | G36: 2026-06-23 | H36: 2026-07-01 | I36: =D36-F36 -> 344704 | J36: =$B$1-G36 -> 8 | K36: =IF(J36<0,"Not Due",IF(J36<=30,"Bucket 1",IF(J36<=60,"Bucket 2",IF(J36<=90,"Bucket 3","NPA")))) -> Bucket 1 | L36: =F36/E36*100 -> 32.09697
A37: CUST0034 | B37: Varsha | C37: Ananya Rao | D37: 900000 | E37: 8500 | F37: 0 | G37: 2026-04-06 | I37: =D37-F37 -> 900000 | J37: =$B$1-G37 -> 86 | K37: =IF(J37<0,"Not Due",IF(J37<=30,"Bucket 1",IF(J37<=60,"Bucket 2",IF(J37<=90,"Bucket 3","NPA")))) -> Bucket 3 | L37: =F37/E37*100 -> 0
A38: CUST0035 | B38: Yogesh | C38: Manish Bhatt | D38: 825000 | E38: 9000 | F38: 0 | G38: 2026-05-27 | I38: =D38-F38 -> 825000 | J38: =$B$1-G38 -> 35 | K38: =IF(J38<0,"Not Due",IF(J38<=30,"Bucket 1",IF(J38<=60,"Bucket 2",IF(J38<=90,"Bucket 3","NPA")))) -> Bucket 2 | L38: =F38/E38*100 -> 0
A39: CUST0036 | B39: Zara | C39: Deepak Chauhan | D39: 450000 | E39: 21000 | F39: 0 | G39: 2026-04-18 | I39: =D39-F39 -> 450000 | J39: =$B$1-G39 -> 74 | K39: =IF(J39<0,"Not Due",IF(J39<=30,"Bucket 1",IF(J39<=60,"Bucket 2",IF(J39<=90,"Bucket 3","NPA")))) -> Bucket 3 | L39: =F39/E39*100 -> 0
A40: CUST0037 | B40: Alok | C40: Ananya Rao | D40: 475000 | E40: 29500 | F40: 29500 | G40: 2026-06-27 | H40: 2026-07-01 | I40: =D40-F40 -> 445500 | J40: =$B$1-G40 -> 4 | K40: =IF(J40<0,"Not Due",IF(J40<=30,"Bucket 1",IF(J40<=60,"Bucket 2",IF(J40<=90,"Bucket 3","NPA")))) -> Bucket 1 | L40: =F40/E40*100 -> 100
A41: CUST0038 | B41: Bina | C41: Farah Sheikh | D41: 900000 | E41: 40000 | F41: 0 | G41: 2026-05-15 | I41: =D41-F41 -> 900000 | J41: =$B$1-G41 -> 47 | K41: =IF(J41<0,"Not Due",IF(J41<=30,"Bucket 1",IF(J41<=60,"Bucket 2",IF(J41<=90,"Bucket 3","NPA")))) -> Bucket 2 | L41: =F41/E41*100 -> 0
...

Sheet Bucket Summary
A1: Outstanding by Aging Bucket
A3: Bucket | B3: Sum of Outstanding
A4: Not Due | B4: =SUMIF('Raw Data'!$K$4:$K$63,A4,'Raw Data'!$I$4:$I$63) -> 4575000
A5: Bucket 1 | B5: =SUMIF('Raw Data'!$K$4:$K$63,A5,'Raw Data'!$I$4:$I$63) -> 6973079
A6: Bucket 2 | B6: =SUMIF('Raw Data'!$K$4:$K$63,A6,'Raw Data'!$I$4:$I$63) -> 11523289
A7: Bucket 3 | B7: =SUMIF('Raw Data'!$K$4:$K$63,A7,'Raw Data'!$I$4:$I$63) -> 4819959
A8: NPA | B8: =SUMIF('Raw Data'!$K$4:$K$63,A8,'Raw Data'!$I$4:$I$63) -> 2521497

Sheet Agent Summary
A1: Collection by Agent
A3: Collection Agent | B3: EMI Collected (₹) | C3: Recovery %
A4: Ananya Rao | B4: =SUMIF('Raw Data'!$C$4:$C$63,A4,'Raw Data'!$F$4:$F$63) -> 284601 | C4: =B4/(SUMIF('Raw Data'!$C$4:$C$63,A4,'Raw Data'!$E$4:$E$63))*100 -> 58.200613
A5: Deepak Chauhan | B5: =SUMIF('Raw Data'!$C$4:$C$63,A5,'Raw Data'!$F$4:$F$63) -> 85231 | C5: =B5/(SUMIF('Raw Data'!$C$4:$C$63,A5,'Raw Data'!$E$4:$E$63))*100 -> 27.186922
A6: Farah Sheikh | B6: =SUMIF('Raw Data'!$C$4:$C$63,A6,'Raw Data'!$F$4:$F$63) -> 195820 | C6: =B6/(SUMIF('Raw Data'!$C$4:$C$63,A6,'Raw Data'!$E$4:$E$63))*100 -> 68.588441
A7: Manish Bhatt | B7: =SUMIF('Raw Data'!$C$4:$C$63,A7,'Raw Data'!$F$4:$F$63) -> 87806 | C7: =B7/(SUMIF('Raw Data'!$C$4:$C$63,A7,'Raw Data'!$E$4:$E$63))*100 -> 23.446195
A8: Ritika Sen | B8: =SUMIF('Raw Data'!$C$4:$C$63,A8,'Raw Data'!$F$4:$F$63) -> 83718 | C8: =B8/(SUMIF('Raw Data'!$C$4:$C$63,A8,'Raw Data'!$E$4:$E$63))*100 -> 32.702344
